<?xml version="1.0" ?>
<sdf version="1.8">
  <model name="husky_panda">
    
    <pose>0 0 0.3 0 0 0</pose>

    <link name="base_link">
      <inertial>
        <mass>33.85</mass>
        <inertia><ixx>2.2</ixx><iyy>3.4</iyy><izz>2.1</izz><ixy>0</ixy><ixz>0</ixz><iyz>0</iyz></inertia>
      </inertial>
      <collision name="base_collision">
        <pose>0 0 0.06 0 0 0</pose>
        <geometry><box><size>1.0 0.40 0.25</size></box></geometry>
      </collision>
      <visual name="base_visual">
        <geometry><mesh><uri>model://husky/meshes/base_link.stl</uri></mesh></geometry>
        <material><ambient>0.2 0.2 0.2 1</ambient><diffuse>0.2 0.2 0.2 1</diffuse></material>
      </visual>
      <visual name="top_plate">
        <geometry><mesh><uri>model://husky/meshes/top_plate.stl</uri></mesh></geometry>
        <material><ambient>0.9 0.8 0.1 1</ambient><diffuse>0.9 0.8 0.1 1</diffuse></material>
      </visual>

      <visual name="camera_visual">
        <pose>0.4 0 0.1 0 0 0</pose>
        <geometry><box><size>0.05 0.05 0.05</size></box></geometry>
        <material><ambient>1 0 0 1</ambient><diffuse>1 0 0 1</diffuse></material>
      </visual>

      <sensor name="husky_camera" type="rgbd">
        <pose>0.4 0 0.1 0 0 0</pose>
        <always_on>1</always_on>
        <update_rate>30</update_rate>
        <visualize>true</visualize>
        <topic>husky_camera</topic>
        <camera>
          <horizontal_fov>1.05</horizontal_fov>
          <image>
            <width>640</width>
            <height>480</height>
            <format>R8G8B8</format>
          </image>
          <clip>
            <near>0.01</near>
            <far>10.0</far>
          </clip>
        </camera>
      </sensor>
    </link>

    <link name="front_left_wheel">
      <pose>0.26 0.285 0.09 0 0 0</pose>
      <inertial>
        <mass>2.637</mass>
        <inertia><ixx>0.02467</ixx><ixy>0</ixy><ixz>0</ixz><iyy>0.04411</iyy><iyz>0</iyz><izz>0.02467</izz></inertia>
      </inertial>
      <collision name="collision">
        <pose>0 0 0 1.5708 0 0</pose>
        <geometry><cylinder><radius>0.177</radius><length>0.114</length></cylinder></geometry>
        <surface><friction><ode><mu>1.0</mu><mu2>1.0</mu2></ode></friction></surface>
      </collision>
      <visual name="visual">
        <geometry><mesh><uri>model://husky/meshes/wheel.stl</uri></mesh></geometry>
        <material><ambient>0.1 0.1 0.1 1</ambient><diffuse>0.1 0.1 0.1 1</diffuse></material>
      </visual>
    </link>
    <joint name="front_left_joint" type="revolute">
      <parent>base_link</parent>
      <child>front_left_wheel</child>
      <axis><xyz>0 1 0</xyz></axis>
    </joint>

    <link name="front_right_wheel">
      <pose>0.26 -0.285 0.09 0 0 0</pose>
      <inertial>
        <mass>2.637</mass>
        <inertia><ixx>0.02467</ixx><ixy>0</ixy><ixz>0</ixz><iyy>0.04411</iyy><iyz>0</iyz><izz>0.02467</izz></inertia>
      </inertial>
      <collision name="collision">
        <pose>0 0 0 1.5708 0 0</pose>
        <geometry><cylinder><radius>0.177</radius><length>0.114</length></cylinder></geometry>
        <surface><friction><ode><mu>1.0</mu><mu2>1.0</mu2></ode></friction></surface>
      </collision>
      <visual name="visual">
        <geometry><mesh><uri>model://husky/meshes/wheel.stl</uri></mesh></geometry>
        <material><ambient>0.1 0.1 0.1 1</ambient><diffuse>0.1 0.1 0.1 1</diffuse></material>
      </visual>
    </link>
    <joint name="front_right_joint" type="revolute">
      <parent>base_link</parent>
      <child>front_right_wheel</child>
      <axis><xyz>0 1 0</xyz></axis>
    </joint>

    <link name="back_left_wheel">
      <pose>-0.26 0.285 0.09 0 0 0</pose>
      <inertial>
        <mass>2.637</mass>
        <inertia><ixx>0.02467</ixx><ixy>0</ixy><ixz>0</ixz><iyy>0.04411</iyy><iyz>0</iyz><izz>0.02467</izz></inertia>
      </inertial>
      <collision name="collision">
        <pose>0 0 0 1.5708 0 0</pose>
        <geometry><cylinder><radius>0.177</radius><length>0.114</length></cylinder></geometry>
        <surface><friction><ode><mu>1.0</mu><mu2>1.0</mu2></ode></friction></surface>
      </collision>
      <visual name="visual">
        <geometry><mesh><uri>model://husky/meshes/wheel.stl</uri></mesh></geometry>
        <material><ambient>0.1 0.1 0.1 1</ambient><diffuse>0.1 0.1 0.1 1</diffuse></material>
      </visual>
    </link>
    <joint name="back_left_joint" type="revolute">
      <parent>base_link</parent>
      <child>back_left_wheel</child>
      <axis><xyz>0 1 0</xyz></axis>
    </joint>

    <link name="back_right_wheel">
      <pose>-0.26 -0.285 0.09 0 0 0</pose>
      <inertial>
        <mass>2.637</mass>
        <inertia><ixx>0.02467</ixx><ixy>0</ixy><ixz>0</ixz><iyy>0.04411</iyy><iyz>0</iyz><izz>0.02467</izz></inertia>
      </inertial>
      <collision name="collision">
        <pose>0 0 0 1.5708 0 0</pose>
        <geometry><cylinder><radius>0.177</radius><length>0.114</length></cylinder></geometry>
        <surface><friction><ode><mu>1.0</mu><mu2>1.0</mu2></ode></friction></surface>
      </collision>
      <visual name="visual">
        <geometry><mesh><uri>model://husky/meshes/wheel.stl</uri></mesh></geometry>
        <material><ambient>0.1 0.1 0.1 1</ambient><diffuse>0.1 0.1 0.1 1</diffuse></material>
      </visual>
    </link>
    <joint name="back_right_joint" type="revolute">
      <parent>base_link</parent>
      <child>back_right_wheel</child>
      <axis><xyz>0 1 0</xyz></axis>
    </joint>

    <joint name="husky_panda_connector" type="fixed">
      <parent>base_link</parent>
      <child>panda_link0</child>
      <pose relative_to="base_link">0.35 0 0.0065 0 0 0</pose> 
    </joint>

    <link name="panda_link0">
      <pose relative_to="husky_panda_connector">0 0 0 0 0 0</pose>
      <visual name="panda_link0_visual">
        <geometry><mesh><uri>model://panda/meshes/visual/link0.dae</uri></mesh></geometry>
      </visual>
      <collision name="panda_link0_collision">
        <geometry><mesh><uri>model://panda/meshes/collision/link0.stl</uri></mesh></geometry>
      </collision>
      <inertial>
        <mass>2.81</mass><inertia><ixx>0.0075</ixx><iyy>0.010</iyy><izz>0.009</izz><ixy>0</ixy><ixz>0</ixz><iyz>0</iyz></inertia>
      </inertial>
    </link>

    <link name="panda_link1">
      <pose relative_to="panda_joint1">0 0 0 0 0 0</pose>
      <visual name="panda_link1_visual"><geometry><mesh><uri>model://panda/meshes/visual/link1.dae</uri></mesh></geometry></visual>
      <collision name="panda_link1_collision"><geometry><mesh><uri>model://panda/meshes/collision/link1.stl</uri></mesh></geometry></collision>
      <inertial><mass>2.64</mass><inertia><ixx>0.017</ixx><iyy>0.015</iyy><izz>0.006</izz><ixy>0</ixy><ixz>0</ixz><iyz>0</iyz></inertia></inertial>
    </link>
    <joint name="panda_joint1" type="revolute">
      <pose relative_to="panda_link0">0 0 0.333 0 0 0</pose>
      <parent>panda_link0</parent> <child>panda_link1</child>
      <axis><xyz>0 0 1</xyz><limit><lower>-2.8973</lower><upper>2.8973</upper><effort>87</effort><velocity>2.175</velocity></limit></axis>
    </joint>

    <link name="panda_link2">
      <pose relative_to="panda_joint2">0 0 0 0 0 0</pose>
      <visual name="panda_link2_visual"><geometry><mesh><uri>model://panda/meshes/visual/link2.dae</uri></mesh></geometry></visual>
      <collision name="panda_link2_collision"><geometry><mesh><uri>model://panda/meshes/collision/link2.stl</uri></mesh></geometry></collision>
      <inertial><mass>2.66</mass><inertia><ixx>0.017</ixx><iyy>0.006</iyy><izz>0.015</izz><ixy>0</ixy><ixz>0</ixz><iyz>0</iyz></inertia></inertial>
    </link>
    <joint name="panda_joint2" type="revolute">
      <pose relative_to="panda_link1">0 0 0 -1.5708 0 0</pose>
      <parent>panda_link1</parent> <child>panda_link2</child>
      <axis><xyz>0 0 1</xyz><limit><lower>-1.7628</lower><upper>1.7628</upper><effort>87</effort><velocity>2.175</velocity></limit></axis>
    </joint>

    <link name="panda_link3">
      <pose relative_to="panda_joint3">0 0 0 0 0 0</pose>
      <visual name="panda_link3_visual"><geometry><mesh><uri>model://panda/meshes/visual/link3.dae</uri></mesh></geometry></visual>
      <collision name="panda_link3_collision"><geometry><mesh><uri>model://panda/meshes/collision/link3.stl</uri></mesh></geometry></collision>
      <inertial><mass>2.32</mass><inertia><ixx>0.007</ixx><iyy>0.009</iyy><izz>0.007</izz><ixy>0</ixy><ixz>0</ixz><iyz>0</iyz></inertia></inertial>
    </link>
    <joint name="panda_joint3" type="revolute">
      <pose relative_to="panda_link2">0 -0.316 0 1.5708 0 0</pose>
      <parent>panda_link2</parent> <child>panda_link3</child>
      <axis><xyz>0 0 1</xyz><limit><lower>-2.8973</lower><upper>2.8973</upper><effort>87</effort><velocity>2.175</velocity></limit></axis>
    </joint>

    <link name="panda_link4">
      <pose relative_to="panda_joint4">0 0 0 0 0 0</pose>
      <visual name="panda_link4_visual"><geometry><mesh><uri>model://panda/meshes/visual/link4.dae</uri></mesh></geometry></visual>
      <collision name="panda_link4_collision"><geometry><mesh><uri>model://panda/meshes/collision/link4.stl</uri></mesh></geometry></collision>
      <inertial><mass>2.31</mass><inertia><ixx>0.007</ixx><iyy>0.008</iyy><izz>0.009</izz><ixy>0</ixy><ixz>0</ixz><iyz>0</iyz></inertia></inertial>
    </link>
    <joint name="panda_joint4" type="revolute">
      <pose relative_to="panda_link3">0.0825 0 0 1.5708 0 0</pose>
      <parent>panda_link3</parent> <child>panda_link4</child>
      <axis><xyz>0 0 1</xyz><limit><lower>-3.0718</lower><upper>-0.0698</upper><effort>87</effort><velocity>2.175</velocity></limit></axis>
    </joint>

    <link name="panda_link5">
      <pose relative_to="panda_joint5">0 0 0 0 0 0</pose>
      <visual name="panda_link5_visual"><geometry><mesh><uri>model://panda/meshes/visual/link5.dae</uri></mesh></geometry></visual>
      <collision name="panda_link5_collision"><geometry><mesh><uri>model://panda/meshes/collision/link5.stl</uri></mesh></geometry></collision>
      <inertial><mass>2.62</mass><inertia><ixx>0.029</ixx><iyy>0.027</iyy><izz>0.004</izz><ixy>0</ixy><ixz>0</ixz><iyz>0</iyz></inertia></inertial>
    </link>
    <joint name="panda_joint5" type="revolute">
      <pose relative_to="panda_link4">-0.0825 0.384 0 -1.5708 0 0</pose>
      <parent>panda_link4</parent> <child>panda_link5</child>
      <axis><xyz>0 0 1</xyz><limit><lower>-2.8973</lower><upper>2.8973</upper><effort>12</effort><velocity>2.61</velocity></limit></axis>
    </joint>

    <link name="panda_link6">
      <pose relative_to="panda_joint6">0 0 0 0 0 0</pose>
      <visual name="panda_link6_visual"><geometry><mesh><uri>model://panda/meshes/visual/link6.dae</uri></mesh></geometry></visual>
      <collision name="panda_link6_collision"><geometry><mesh><uri>model://panda/meshes/collision/link6.stl</uri></mesh></geometry></collision>
      <inertial><mass>1.50</mass><inertia><ixx>0.002</ixx><iyy>0.003</iyy><izz>0.005</izz><ixy>0</ixy><ixz>0</ixz><iyz>0</iyz></inertia></inertial>
    </link>
    <joint name="panda_joint6" type="revolute">
      <pose relative_to="panda_link5">0 0 0 1.5708 0 0</pose>
      <parent>panda_link5</parent> <child>panda_link6</child>
      <axis><xyz>0 0 1</xyz><limit><lower>-0.0175</lower><upper>3.7525</upper><effort>12</effort><velocity>2.61</velocity></limit></axis>
    </joint>

    <link name="panda_link7">
      <pose relative_to="panda_joint7">0 0 0 0 0 0</pose>
      <visual name="panda_link7_visual"><geometry><mesh><uri>model://panda/meshes/visual/link7.dae</uri></mesh></geometry></visual>
      <collision name="panda_link7_collision"><geometry><mesh><uri>model://panda/meshes/collision/link7.stl</uri></mesh></geometry></collision>
      <inertial><mass>0.52</mass><inertia><ixx>0.0008</ixx><iyy>0.0008</iyy><izz>0.0006</izz><ixy>0</ixy><ixz>0</ixz><iyz>0</iyz></inertia></inertial>
    </link>
    <joint name="panda_joint7" type="revolute">
      <pose relative_to="panda_link6">0.088 0 0 1.5708 0 0</pose>
      <parent>panda_link6</parent> <child>panda_link7</child>
      <axis><xyz>0 0 1</xyz><limit><lower>-2.8973</lower><upper>2.8973</upper><effort>12</effort><velocity>2.61</velocity></limit></axis>
    </joint>

    <joint name="panda_hand_joint" type="fixed">
      <pose relative_to="panda_link7">0 0 0.107 0 0 -0.7854</pose>
      <parent>panda_link7</parent> <child>panda_hand</child>
    </joint>

    <link name="panda_hand">
      <pose relative_to="panda_hand_joint">0 0 0 0 0 0</pose>
      <visual name="panda_hand_visual"><geometry><mesh><uri>model://panda/meshes/visual/hand.dae</uri></mesh></geometry></visual>
      <collision name="panda_hand_collision"><geometry><mesh><uri>model://panda/meshes/collision/hand.stl</uri></mesh></geometry></collision>
      <inertial>
        <mass>0.14</mass>
        <inertia><ixx>0.00054</ixx><iyy>0.00008</iyy><izz>0.00050</izz><ixy>0</ixy><ixz>0</ixz><iyz>0</iyz></inertia>
      </inertial>
    </link>

    <link name="panda_leftfinger">
      <pose relative_to="panda_finger_joint1">0 0 0 0 0 0</pose>
      <visual name="panda_leftfinger_visual"><geometry><mesh><uri>model://panda/meshes/visual/finger.dae</uri></mesh></geometry></visual>
      <collision name="panda_leftfinger_collision"><geometry><mesh><uri>model://panda/meshes/collision/finger.stl</uri></mesh></geometry></collision>
      <inertial><mass>0.22</mass><inertia><ixx>0.00006</ixx><iyy>0.00006</iyy><izz>0.00001</izz><ixy>0</ixy><ixz>0</ixz><iyz>0</iyz></inertia></inertial>
    </link>

    <link name="panda_rightfinger">
      <pose relative_to="panda_finger_joint2">0 0 0 0 0 0</pose>
      <visual name="panda_rightfinger_visual"><pose>0 0 0 0 0 3.14159</pose><geometry><mesh><uri>model://panda/meshes/visual/finger.dae</uri></mesh></geometry></visual>
      <collision name="panda_rightfinger_collision"><pose>0 0 0 0 0 3.14159</pose><geometry><mesh><uri>model://panda/meshes/collision/finger.stl</uri></mesh></geometry></collision>
      <inertial><mass>0.22</mass><inertia><ixx>0.00006</ixx><iyy>0.00006</iyy><izz>0.00001</izz><ixy>0</ixy><ixz>0</ixz><iyz>0</iyz></inertia></inertial>
    </link>

    <joint name="panda_finger_joint1" type="prismatic">
      <pose relative_to="panda_hand">0 0 0.0584 0 0 0</pose>
      <parent>panda_hand</parent> <child>panda_leftfinger</child>
      <axis><xyz>0 1 0</xyz><limit><lower>0</lower><upper>0.04</upper></limit></axis>
    </joint>
    <joint name="panda_finger_joint2" type="prismatic">
      <pose relative_to="panda_hand">0 0 0.0584 0 0 0</pose>
      <parent>panda_hand</parent> <child>panda_rightfinger</child>
      <axis><xyz>0 -1 0</xyz><limit><lower>0</lower><upper>0.04</upper></limit></axis>
    </joint>

    <plugin filename="libign_ros2_control-system.so" name="ign_ros2_control::IgnitionROS2ControlPlugin">
  <parameters>/home/moonlab/ros_ws/src/husky_panda_sim/config/husky_panda_controllers.yaml</parameters>
</plugin>
    <ros2_control name="IgnitionSystem" type="system">
      <hardware>
        <plugin>ign_ros2_control/IgnitionSystem</plugin>
      </hardware>

      <joint name="front_left_joint"><command_interface name="velocity"/><state_interface name="velocity"/><state_interface name="position"/></joint>
      <joint name="front_right_joint"><command_interface name="velocity"/><state_interface name="velocity"/><state_interface name="position"/></joint>
      <joint name="back_left_joint"><command_interface name="velocity"/><state_interface name="velocity"/><state_interface name="position"/></joint>
      <joint name="back_right_joint"><command_interface name="velocity"/><state_interface name="velocity"/><state_interface name="position"/></joint>

      <joint name="panda_joint1">
        <command_interface name="position"><param name="min">-2.8973</param><param name="max">2.8973</param></command_interface>
        <state_interface name="position"/><state_interface name="velocity"/>
      </joint>
      <joint name="panda_joint2">
        <command_interface name="position"><param name="min">-1.7628</param><param name="max">1.7628</param></command_interface>
        <state_interface name="position"/><state_interface name="velocity"/>
      </joint>
      <joint name="panda_joint3">
        <command_interface name="position"><param name="min">-2.8973</param><param name="max">2.8973</param></command_interface>
        <state_interface name="position"/><state_interface name="velocity"/>
      </joint>
      <joint name="panda_joint4">
        <command_interface name="position"><param name="min">-3.0718</param><param name="max">-0.0698</param></command_interface>
        <state_interface name="position"/><state_interface name="velocity"/>
      </joint>
      <joint name="panda_joint5">
        <command_interface name="position"><param name="min">-2.8973</param><param name="max">2.8973</param></command_interface>
        <state_interface name="position"/><state_interface name="velocity"/>
      </joint>
      <joint name="panda_joint6">
        <command_interface name="position"><param name="min">-0.0175</param><param name="max">3.7525</param></command_interface>
        <state_interface name="position"/><state_interface name="velocity"/>
      </joint>
      <joint name="panda_joint7">
        <command_interface name="position"><param name="min">-2.8973</param><param name="max">2.8973</param></command_interface>
        <state_interface name="position"/><state_interface name="velocity"/>
      </joint>

      <joint name="panda_finger_joint1">
        <command_interface name="position"><param name="min">0.0</param><param name="max">0.04</param></command_interface>
        <state_interface name="position"/><state_interface name="velocity"/>
      </joint>
      <joint name="panda_finger_joint2">
        <command_interface name="position"><param name="min">0.0</param><param name="max">0.04</param></command_interface>
        <state_interface name="position"/><state_interface name="velocity"/>
      </joint>
    </ros2_control>


    <plugin
      filename="libignition-gazebo-diff-drive-system.so"
      name="ignition::gazebo::systems::DiffDrive">
      
      <left_joint>front_left_joint</left_joint>
      <left_joint>back_left_joint</left_joint>
      <right_joint>front_right_joint</right_joint>
      <right_joint>back_right_joint</right_joint>

      <wheel_separation>0.57</wheel_separation>
      <wheel_radius>0.165</wheel_radius>
      <odom_publish_frequency>20</odom_publish_frequency>
      
      <topic>/cmd_vel</topic> <odom_topic>/odom</odom_topic>
      <tf_topic>/tf</tf_topic>
      <frame_id>odom</frame_id>
      <child_frame_id>base_link</child_frame_id>
    </plugin>

  

  </model>
</sdf>